<?xml version="1.0" ?>
<!-- =================================================================================== -->
<!-- |    This document was autogenerated by xacro from ax12_arm_robot.xacro           | -->
<!-- |    EDITING THIS FILE BY HAND IS NOT RECOMMENDED                                 | -->
<!-- =================================================================================== -->
<robot name="ax12_arm" xmlns:controller="http://playerstage.sourceforge.net/gazebo/xmlschema/#controller" xmlns:interface="http://playerstage.sourceforge.net/gazebo/xmlschema/#interface" xmlns:sensor="http://playerstage.sourceforge.net/gazebo/xmlschema/#sensor" xmlns:xacro="http://www.ros.org/wiki/xacro">
  <!-- Included URDF Files -->
  <material name="Grey">
    <color rgba="0.5 0.5 0.5 1.0"/>
  </material>
  <material name="DarkGrey">
    <color rgba="0.3 0.3 0.3 1.0"/>
  </material>
  <material name="Red">
    <color rgba="0.9 0.2 0.2 1.0"/>
  </material>
  <material name="Blue">
    <color rgba="0.2 0.2 0.9 1.0"/>
  </material>
  <link name="base_link">
    <visual>
      <origin rpy="0 0 0" xyz="0 0 0"/>
      <geometry>
        <box size="0.001 0.001 0.001"/>
      </geometry>
    </visual>
    <collision>
      <origin rpy="0 0 0" xyz="0 0 0"/>
      <geometry>
        <box size="0.001 0.001 0.001"/>
      </geometry>
    </collision>
  </link>
  <joint name="arm_base_joint" type="fixed">
    <origin rpy="0 0 0" xyz="0 0 0"/>
    <parent link="base_link"/>
    <child link="arm_base_link"/>
  </joint>
  <joint name="shoulder_pan_joint" type="revolute">
    <origin rpy="0 0 0" xyz="-0.0075 0 0.025"/>
    <parent link="arm_base_link"/>
    <child link="arm_shoulder_pan_link"/>
    <axis xyz="0 0 1"/>
    <limit effort="300" lower="-1.6" upper="1.6" velocity="0.4"/>
    <safety_controller k_position="100" k_velocity="15.0" soft_lower_limit="-1.12" soft_upper_limit="1.12"/>
    <dynamics damping="50" friction="1"/>
  </joint>
  <joint name="shoulder_pitch_joint" type="revolute">
    <origin rpy="0 -0.7854 0" xyz="0.044 0 0.090"/>
    <parent link="arm_shoulder_pan_link"/>
    <child link="arm_shoulder_pitch_link"/>
    <axis xyz="0 1 0"/>
    <limit effort="300" lower="-1.5" upper="1.2" velocity="0.4"/>
    <safety_controller k_position="100" k_velocity="15.0" soft_lower_limit="-0.94719755" soft_upper_limit="1.872222"/>
    <dynamics damping="50" friction="1"/>
  </joint>
  <joint name="elbow_flex_joint" type="revolute">
    <origin rpy="0 0 0" xyz="0.1815 0 0"/>
    <parent link="arm_shoulder_pitch_link"/>
    <child link="arm_elbow_flex_link"/>
    <axis xyz="0 -1 0"/>
    <limit effort="300" lower="-1.5" upper="1.5" velocity="0.4"/>
    <dynamics damping="50" friction="1"/>
    <safety_controller k_position="100" k_velocity="15.0" soft_lower_limit="-1.872222" soft_upper_limit="1.7849556"/>
  </joint>
  <joint name="wrist_roll_joint" type="revolute">
    <origin rpy="3.14159 0 0" xyz="0.07 0 0.023"/>
    <parent link="arm_elbow_flex_link"/>
    <child link="gripper_roll_link"/>
    <axis xyz="1 0 0"/>
    <limit effort="300" lower="-1.5" upper="1.5" velocity="1.17"/>
    <dynamics damping="50" friction="1"/>
    <safety_controller k_position="100" k_velocity="15.0" soft_lower_limit="-2.5179939" soft_upper_limit="2.5179939"/>
  </joint>
  <link name="arm_base_link">
    <inertial>
      <mass value="0.125"/>
      <origin rpy="0 0 0" xyz="0 0 0.00893364"/>
      <inertia ixx="1.0" ixy="0.0" ixz="0.0" iyy="1.0" iyz="0.0" izz="1.0"/>
    </inertial>
    <visual>
      <origin rpy="0 0 0" xyz="0.0 0.0 0.0"/>
      <geometry>
        <mesh filename="package://ax12_description/meshes/stl/arm_base.stl"/>
      </geometry>
      <material name="Grey"/>
    </visual>
    <collision>
      <origin rpy="0 0 0" xyz="0.0 0.0 0.0"/>
      <geometry>
        <mesh filename="package://ax12_description/meshes/stl/arm_base.stl"/>
      </geometry>
    </collision>
  </link>
  <link name="arm_shoulder_pan_link">
    <inertial>
      <mass value="0.405"/>
      <origin rpy="0 0 0" xyz="0.02988871 0 0.02056699"/>
      <inertia ixx="1.0" ixy="0.0" ixz="0.0" iyy="1.0" iyz="0.0" izz="1.0"/>
    </inertial>
    <visual>
      <origin rpy="0 0 0" xyz="0.0 0.0 0.005"/>
      <geometry>
        <mesh filename="package://ax12_description/meshes/stl/arm_shoulder_pan_new.stl"/>
      </geometry>
      <material name="DarkGrey"/>
    </visual>
    <collision>
      <origin rpy="0 0 0" xyz="0.0 0.0 0.0"/>
      <geometry>
        <mesh filename="package://ax12_description/meshes/stl/arm_shoulder_pan_new.stl"/>
      </geometry>
    </collision>
  </link>
  <link name="arm_shoulder_pitch_link">
    <inertial>
      <mass value="0.18"/>
      <origin rpy="0 0 0" xyz="0.13999458 0 0.00064711"/>
      <inertia ixx="1.0" ixy="0.0" ixz="0.0" iyy="1.0" iyz="0.0" izz="1.0"/>
    </inertial>
    <visual>
      <origin rpy="0 0 0" xyz="0.0 0.0 0.0"/>
      <geometry>
        <mesh filename="package://ax12_description/meshes/stl/arm_shoulder_pitch.stl"/>
      </geometry>
      <material name="Grey"/>
    </visual>
    <collision>
      <origin rpy="0 0 0" xyz="0.0 0.0 0.0"/>
      <geometry>
        <mesh filename="package://ax12_description/meshes/stl/arm_shoulder_pitch.stl"/>
      </geometry>
    </collision>
  </link>
  <link name="arm_elbow_flex_link">
    <inertial>
      <mass value="0.12"/>
      <origin rpy="0 0 0" xyz="0.04463361 0 0.00720194"/>
      <inertia ixx="1.0" ixy="0.0" ixz="0.0" iyy="1.0" iyz="0.0" izz="1.0"/>
    </inertial>
    <visual>
      <origin rpy="0 0 0" xyz="0.0 0.0 0.0"/>
      <geometry>
        <mesh filename="package://ax12_description/meshes/stl/arm_elbow_flex.stl"/>
      </geometry>
      <material name="DarkGrey"/>
    </visual>
    <collision>
      <origin rpy="0 0 0" xyz="0.0 0.0 0.0"/>
      <geometry>
        <mesh filename="package://ax12_description/meshes/stl/arm_elbow_flex.stl"/>
      </geometry>
    </collision>
  </link>
  <transmission name="shoulder_pan_trans" type="pr2_mechanism_model/SimpleTransmission">
    <actuator name="shoulder_pan_motor"/>
    <joint name="shoulder_pan_joint"/>
    <mechanicalReduction>1.0</mechanicalReduction>
  </transmission>
  <transmission name="shoulder_pitch_trans" type="pr2_mechanism_model/SimpleTransmission">
    <actuator name="shoulder_pitch_motor"/>
    <joint name="shoulder_pitch_joint"/>
    <mechanicalReduction>1.0</mechanicalReduction>
  </transmission>
  <transmission name="elbow_flex_trans" type="pr2_mechanism_model/SimpleTransmission">
    <actuator name="elbow_flex_motor"/>
    <joint name="elbow_flex_joint"/>
    <mechanicalReduction>1.0</mechanicalReduction>
  </transmission>
  <transmission name="wrist_roll_trans" type="pr2_mechanism_model/SimpleTransmission">
    <actuator name="wrist_roll_motor"/>
    <joint name="wrist_roll_joint"/>
    <mechanicalReduction>1.0</mechanicalReduction>
  </transmission>
  <gazebo reference="arm_base_link">
    <material>Gazebo/Grey</material>
    <turnGravityOff>false</turnGravityOff>
  </gazebo>
  <gazebo reference="arm_shoulder_pan_link">
    <material>Gazebo/Grey</material>
    <turnGravityOff>false</turnGravityOff>
  </gazebo>
  <gazebo reference="arm_shoulder_pitch_link">
    <material>Gazebo/Grey</material>
    <turnGravityOff>false</turnGravityOff>
  </gazebo>
  <gazebo reference="arm_elbow_flex_link">
    <material>Gazebo/Grey</material>
    <turnGravityOff>false</turnGravityOff>
  </gazebo>
  <gazebo reference="shoulder_pan_joint">
    <stopKd value="1.0"/>
    <stopKp value="1000000.0"/>
    <fudgeFactor value="0.5"/>
  </gazebo>
  <gazebo reference="shoulder_pitch_joint">
    <stopKd value="1.0"/>
    <stopKp value="1000000.0"/>
    <fudgeFactor value="0.5"/>
  </gazebo>
  <gazebo reference="elbow_flex_joint">
    <stopKd value="1.0"/>
    <stopKp value="1000000.0"/>
    <fudgeFactor value="0.5"/>
  </gazebo>
  <link name="gripper_roll_link">
    <inertial>
      <origin xyz="0 0 0"/>
      <mass value="1.0"/>
      <inertia ixx="1.0" ixy="0.0" ixz="0.0" iyy="1.0" iyz="0.0" izz="1.0"/>
    </inertial>
    <visual>
      <origin rpy="0 0 0" xyz="0 0 0"/>
      <geometry>
        <mesh filename="package://ax12_description/meshes/stl/gripper_roll_link_scaled.stl"/>
      </geometry>
      <material name="Grey"/>
    </visual>
    <collision>
      <origin rpy="0 0 0" xyz="0 0 0"/>
      <geometry>
        <mesh filename="package://ax12_description/meshes/stl/gripper_roll_link_scaled.stl"/>
      </geometry>
    </collision>
  </link>
  <gazebo reference="gripper_roll_link">
    <material>Gazebo/Grey</material>
    <turnGravityOff>false</turnGravityOff>
  </gazebo>
  <joint name="gripper_joint" type="revolute">
    <parent link="gripper_roll_link"/>
    <child link="gripper_finger_link"/>
    <origin rpy="2.58 1.570795 0.603534345556" xyz="0.026 0.018  0"/>
    <axis xyz="1 0 0"/>
    <limit effort="300" lower="-0.15" upper="0.55" velocity="1"/>
    <dynamics damping="50" friction="1"/>
  </joint>
  <link name="gripper_finger_link">
    <inertial>
      <origin xyz="0 0 0"/>
      <mass value="1.0"/>
      <inertia ixx="1.0" ixy="0.0" ixz="0.0" iyy="1.0" iyz="0.0" izz="1.0"/>
    </inertial>
    <visual>
      <origin rpy="0 0 3.14159" xyz="0 0 0"/>
      <geometry>
        <mesh filename="package://ax12_description/meshes/stl/l_gripper_aft_link.STL"/>
      </geometry>
      <material name="Blue"/>
    </visual>
    <collision>
      <origin rpy="0 0 3.14159" xyz="0 0 0"/>
      <geometry>
        <mesh filename="package://ax12_description/meshes/stl/l_gripper_aft_link.STL"/>
      </geometry>
    </collision>
  </link>
  <gazebo reference="gripper_finger_link">
    <material>Gazebo/Blue</material>
    <turnGravityOff>false</turnGravityOff>
  </gazebo>
  <joint name="r_gripper_aft_joint" type="revolute">
    <parent link="gripper_roll_link"/>
    <child link="r_gripper_aft_link"/>
    <origin rpy="-1.35 1.570795 0.603534345556" xyz="0.026 -0.011  0"/>
    <axis xyz="1 0 0"/>
    <limit effort="300" lower="-0.55" upper="0.15" velocity="1"/>
    <dynamics damping="50" friction="1"/>
  </joint>
  <link name="r_gripper_aft_link">
    <inertial>
      <origin xyz="0 0 0"/>
      <mass value="1.0"/>
      <inertia ixx="1.0" ixy="0.0" ixz="0.0" iyy="100.0" iyz="0.0" izz="1.0"/>
    </inertial>
    <visual>
      <origin rpy="0 0 3.14159" xyz="0 0 0"/>
      <geometry>
        <mesh filename="package://ax12_description/meshes/stl/r_gripper_aft_link.STL"/>
      </geometry>
      <material name="Blue"/>
    </visual>
    <collision>
      <origin rpy="0 0 3.14159" xyz="0 0 0"/>
      <geometry>
        <mesh filename="package://ax12_description/meshes/stl/r_gripper_aft_link.STL"/>
      </geometry>
    </collision>
  </link>
  <gazebo reference="r_gripper_aft_link">
    <material>Gazebo/Blue</material>
    <turnGravityOff>false</turnGravityOff>
  </gazebo>
  <joint name="l_gripper_fwd_joint" type="revolute">
    <parent link="gripper_roll_link"/>
    <child link="l_gripper_fwd_link"/>
    <origin rpy="2.6 1.570795 3.74512434556" xyz="0.05 0.008 0.007"/>
    <axis xyz="1 0 0"/>
    <limit effort="300" lower="-0.15" upper="0.55" velocity="1"/>
    <dynamics damping="50" friction="1"/>
  </joint>
  <link name="l_gripper_fwd_link">
    <inertial>
      <origin xyz="0 0 0"/>
      <mass value="1.0"/>
      <inertia ixx="1.0" ixy="0.0" ixz="0.0" iyy="100.0" iyz="0.0" izz="1.0"/>
    </inertial>
    <visual>
      <origin rpy="0 0 3.14159" xyz="0 0 0"/>
      <geometry>
        <mesh filename="package://ax12_description/meshes/stl/l_gripper_fwd_link.STL"/>
      </geometry>
      <material name="Blue"/>
    </visual>
    <collision>
      <origin rpy="0 0 3.14159" xyz="0 0 0"/>
      <geometry>
        <mesh filename="package://ax12_description/meshes/stl/l_gripper_fwd_link.STL"/>
      </geometry>
    </collision>
  </link>
  <gazebo reference="l_gripper_fwd_link">
    <material>Gazebo/Blue</material>
    <turnGravityOff>false</turnGravityOff>
  </gazebo>
  <joint name="r_gripper_fwd_joint" type="revolute">
    <parent link="gripper_roll_link"/>
    <child link="r_gripper_fwd_link"/>
    <origin rpy="3.7 1.570795 2.53805565444" xyz="0.05 -0.0014 0.007"/>
    <axis xyz="1 0 0"/>
    <limit effort="300" lower="-0.55" upper="0.15" velocity="1"/>
    <dynamics damping="50" friction="1"/>
  </joint>
  <link name="r_gripper_fwd_link">
    <inertial>
      <origin xyz="0 0 0"/>
      <mass value="1.0"/>
      <inertia ixx="1.0" ixy="0.0" ixz="0.0" iyy="100.0" iyz="0.0" izz="1.0"/>
    </inertial>
    <visual>
      <origin rpy="0 0 3.14159" xyz="0 0 0"/>
      <geometry>
        <mesh filename="package://ax12_description/meshes/stl/r_gripper_fwd_link.STL"/>
      </geometry>
      <material name="Blue"/>
    </visual>
    <collision>
      <origin rpy="0 0 3.14159" xyz="0 0 0"/>
      <geometry>
        <mesh filename="package://ax12_description/meshes/stl/r_gripper_fwd_link.STL"/>
      </geometry>
    </collision>
  </link>
  <gazebo reference="r_gripper_fwd_link">
    <material>Gazebo/Blue</material>
    <turnGravityOff>false</turnGravityOff>
  </gazebo>
  <joint name="gripper_finger_pincher_joint" type="revolute">
    <parent link="gripper_finger_link"/>
    <child link="l_gripper_pincher_link"/>
    <origin rpy="-2.99159 0 0" xyz="-0.0032 0 -0.0508"/>
    <axis xyz="1 0 0"/>
    <limit effort="300" lower="-0.55" upper="0.15" velocity="1"/>
    <dynamics damping="50" friction="1"/>
  </joint>
  <link name="l_gripper_pincher_link">
    <inertial>
      <origin xyz="0 0 0"/>
      <mass value="1.0"/>
      <inertia ixx="1.0" ixy="0.0" ixz="0.0" iyy="100.0" iyz="0.0" izz="1.0"/>
    </inertial>
    <visual>
      <origin rpy="0 0 3.14159" xyz="0 0 0"/>
      <geometry>
        <mesh filename="package://ax12_description/meshes/stl/l_gripper_pincher.STL"/>
      </geometry>
      <material name="Red"/>
    </visual>
    <collision>
      <origin rpy="0 0 3.14159" xyz="0 0 0"/>
      <geometry>
        <mesh filename="package://ax12_description/meshes/stl/l_gripper_pincher.STL"/>
      </geometry>
    </collision>
  </link>
  <gazebo reference="l_gripper_pincher_link">
    <material>Gazebo/Red</material>
    <turnGravityOff>false</turnGravityOff>
  </gazebo>
  <joint name="r_gripper_aft_pincher_joint" type="revolute">
    <parent link="r_gripper_aft_link"/>
    <child link="r_gripper_pincher_link"/>
    <origin rpy="0.15 3.14159 0" xyz="0 0 -0.0508"/>
    <axis xyz="1 0 0"/>
    <limit effort="300" lower="-0.55" upper="0.15" velocity="1"/>
    <dynamics damping="50" friction="1"/>
  </joint>
  <link name="r_gripper_pincher_link">
    <inertial>
      <origin xyz="0 0 0"/>
      <mass value="1.0"/>
      <inertia ixx="1.0" ixy="0.0" ixz="0.0" iyy="100.0" iyz="0.0" izz="1.0"/>
    </inertial>
    <visual>
      <origin rpy="0 0 3.14159" xyz="0 0 0"/>
      <geometry>
        <mesh filename="package://ax12_description/meshes/stl/r_gripper_pincher.STL"/>
      </geometry>
      <material name="Red"/>
    </visual>
    <collision>
      <origin rpy="0 0 3.14159" xyz="0 0 0"/>
      <geometry>
        <mesh filename="package://ax12_description/meshes/stl/r_gripper_pincher.STL"/>
      </geometry>
    </collision>
  </link>
  <gazebo reference="r_gripper_pincher_link">
    <material>Gazebo/Red</material>
    <turnGravityOff>false</turnGravityOff>
  </gazebo>
</robot>
